Workbook

Sheet Cover
A3: ALASKA AIR GROUP, INC. (NYSE: ALK)
A5: FORENSIC ACCOUNTING DATA BOOK
A7: Supporting Schedules for:
A8: The 10-Sigma Anomaly: Undisclosed Cybersecurity Crisis
A9: and $120M Accounting Irregularities
A12: December 2025
A15: CONTENTS
A17: Schedule 1 | B17: SEC Filing Data - Alaska Air Group | C17: Raw quarterly data from 10-Q/10-K filings
A18: Schedule 2 | B18: SEC Filing Data - Peer Airlines | C18: United, Delta, American comparative data
A19: Schedule 3 | B19: Issuance-to-Revenue Analysis | C19: The 10.40σ anomaly calculation
A20: Schedule 4 | B20: Partner Redemption Analysis | C20: The $45M excess calculation
A21: Schedule 5 | B21: Balance Sheet Trail | C21: Receivable spike and NCA reclassification
A22: Schedule 6 | B22: Materiality Assessment | C22: SAB 99 analysis
A23: Schedule 7 | B23: Financial Impact | C23: Financial Statdement Overall Assessment
A25: COLOUR KEY
A26: Blue text | B26: Hardcoded input from SEC filing
A27: Green text | B27: Formula linking to another schedule
A28: Black text | B28: Calculated formula
A29: Yellow highlight | B29: Key assumption
A30: Red highlight | B30: Key finding / anomaly

Sheet Sch1 ALK SEC Data
A1: SCHEDULE 1: ALASKA AIR GROUP - SEC FILING DATA
A2: Source: 10-Q and 10-K filings, EDGAR. All figures in $M unless stated.
A4: Period | B4: Q3 2022 | C4: Q4 2022 | D4: Q1 2023 | E4: Q2 2023 | F4: Q3 2023 | G4: Q4 2023 | H4: Q1 2024 | I4: Q2 2024 | J4: Q3 2024 | K4: Q4 2024 | L4: Q1 2025 | M4: Q2 2025 | N4: Q3 2025
A5: BALANCE SHEET ITEMS
A6: Other Non-Current Assets | B6: 422 | C6: 380 | D6: 374 | E6: 268 | F6: 290 | G6: 292 | H6: 283 | I6: 270 | J6: 363 | K6: 334 | L6: 334 | M6: 316 | N6: 436
A7: Receivables from Affinity Card Partners | B7: 80 | C7: 83 | D7: 94 | E7: 96 | F7: 91 | G7: 102 | H7: 104 | I7: 87 | J7: 105 | K7: 176 | L7: 111 | M7: 306 | N7: 177
A9: LOYALTY PROGRAMME ITEMS (QUARTERLY)
A10: Loyalty Points Issued (Quarterly) | B10: 282 | C10: 282 | D10: 285 | E10: 317 | F10: 298 | G10: 297 | H10: 292 | I10: 321 | J10: 334 | K10: 453 | L10: 414 | M10: 576 | N10: 374
A11: Loyalty Redemptions - Passenger (Quarterly) | B11: 223 | C11: 246 | D11: 218 | E11: 252 | F11: 242 | G11: 262 | H11: 234 | I11: 274 | J11: 274 | K11: 342 | L11: 307 | M11: 348 | N11: 338
A12: Loyalty Redemptions - Partner (Quarterly) | B12: 19 | C12: 20 | D12: 21 | E12: 31 | F12: 34 | G12: 31 | H12: 28 | I12: 39 | J12: 46 | K12: 47 | L12: 49 | M12: 70 | N12: 75
A13: Loyalty Other Revenue (Quarterly) | B13: 146 | C13: 157 | D13: 154 | E13: 170 | F13: 159 | G13: 165 | H13: 164 | I13: 174 | J13: 171 | K13: 224 | L13: 207 | M13: 210 | N13: 200
A15: *105 publshed in Q4 2024 and Q1 2025, re-stated without commentary to 176 in Q2 and Q3 2025
A16: Source: Alaska Air Group 10-Q filings (Q1-Q3 each year) and 10-K filings (Q4/FY), SEC EDGAR
A17: Hyperlinked to precise SEC filing number

Sheet Sch2 Peers SEC Data
A1: SCHEDULE 2: PEER AIRLINES - SEC FILING DATA
A2: Source: 10-Q and 10-K filings, EDGAR. All figures in $M unless stated.
A4: Period | B4: Q3 2022 | C4: Q4 2022 | D4: Q1 2023 | E4: Q2 2023 | F4: Q3 2023 | G4: Q4 2023 | H4: Q1 2024 | I4: Q2 2024 | J4: Q3 2024 | K4: Q4 2024 | L4: Q1 2025 | M4: Q2 2025 | N4: Q3 2025
A5: UNITED AIRLINES (UAL)
A6: Points Issued (Quarterly) | B6: 705 | C6: 710 | D6: 747 | E6: 902 | F6: 816 | G6: 832 | H6: 840 | I6: 919 | J6: 884 | K6: 920 | L6: 919 | M6: 991 | N6: 968
A7: Other Marketing Revenue (Quarterly) | B7: 600 | C7: 700 | D7: 646 | E7: 654 | F7: 700 | G7: 700 | H7: 714 | I7: 786 | J7: 700 | K7: 700 | L7: 774 | M7: 826 | N7: 800
A9: DELTA AIR LINES (DAL)
A10: Points Issued (Quarterly) | B10: 938 | C10: 923 | D10: 999 | E10: 1111 | F10: 1054 | G10: 1009 | H10: 1021 | I10: 1127 | J10: 1155 | K10: 1160 | L10: 1152 | M10: 1235 | N10: 1218
A11: Loyalty Program Revenue (Quarterly) | B11: 656 | C11: 720 | D11: 726 | E11: 774 | F11: 791 | G11: 802 | H11: 795 | I11: 836 | J11: 820 | K11: 846 | L11: 807 | M11: 855 | N11: 847
A13: AMERICAN AIRLINES (AAL)
A14: Points Issued (Quarterly) | B14: 771 | C14: 854 | D14: 788 | E14: 1214 | F14: 898 | G14: 910 | H14: 1159 | I14: 1009 | J14: 937 | K14: 1377 | L14: 1204 | M14: 1074 | N14: 1084
A15: Loyalty Revenue - Marketing (Quarterly) | B15: 613 | C15: 892 | D15: 613 | E15: 539 | F15: 613 | G15: 1164 | H15: 786 | I15: 798 | J15: 779 | K15: 894 | L15: 823 | M15: 912 | N15: 831
A17: Q3 2025 hyperlinked to precise SEC filing number

Sheet Sch3 Issuance Analysis
A1: SCHEDULE 3: ISSUANCE-TO-REVENUE RATIO ANALYSIS
A2: The 10.40σ Anomaly - Statistical Analysis
A4: A. QUARTERLY DATA
A5: Period | B5: Q3 2022 | C5: Q4 2022 | D5: Q1 2023 | E5: Q2 2023 | F5: Q3 2023 | G5: Q4 2023 | H5: Q1 2024 | I5: Q2 2024 | J5: Q3 2024 | K5: Q4 2024 | L5: Q1 2025 | M5: Q2 2025 | N5: Q3 2025
A6: ALK: Points Issued ($M) | B6: ='Sch1 ALK SEC Data'!B10 -> 282 | C6: ='Sch1 ALK SEC Data'!C10 -> 282 | D6: ='Sch1 ALK SEC Data'!D10 -> 285 | E6: ='Sch1 ALK SEC Data'!E10 -> 317 | F6: ='Sch1 ALK SEC Data'!F10 -> 298 | G6: ='Sch1 ALK SEC Data'!G10 -> 297 | H6: ='Sch1 ALK SEC Data'!H10 -> 292 | I6: ='Sch1 ALK SEC Data'!I10 -> 321 | ... N6: ='Sch1 ALK SEC Data'!N10 -> 374
A7: ALK: Loyalty Other Revenue ($M) | B7: ='Sch1 ALK SEC Data'!B13 -> 146 | C7: ='Sch1 ALK SEC Data'!C13 -> 157 | D7: ='Sch1 ALK SEC Data'!D13 -> 154 | E7: ='Sch1 ALK SEC Data'!E13 -> 170 | F7: ='Sch1 ALK SEC Data'!F13 -> 159 | G7: ='Sch1 ALK SEC Data'!G13 -> 165 | H7: ='Sch1 ALK SEC Data'!H13 -> 164 | I7: ='Sch1 ALK SEC Data'!I13 -> 174 | ... N7: ='Sch1 ALK SEC Data'!N13 -> 200
A8: ALK: Issuance-to-Revenue Ratio | B8: =B6/B7 -> 1.9315068 | C8: =C6/C7 -> 1.7961783 | D8: =D6/D7 -> 1.8506494 | E8: =E6/E7 -> 1.8647059 | F8: =F6/F7 -> 1.8742138 | G8: =G6/G7 -> 1.8 | H8: =H6/H7 -> 1.7804878 | I8: =I6/I7 -> 1.8448276 | ... N8: =N6/N7 -> 1.87
A10: UAL: Issuance-to-Revenue Ratio | B10: ='Sch2 Peers SEC Data'!B6/'Sch2 Peers SEC Data'!B7 -> 1.175 | C10: ='Sch2 Peers SEC Data'!C6/'Sch2 Peers SEC Data'!C7 -> 1.0142857 | D10: ='Sch2 Peers SEC Data'!D6/'Sch2 Peers SEC Data'!D7 -> 1.1563467 | E10: ='Sch2 Peers SEC Data'!E6/'Sch2 Peers SEC Data'!E7 -> 1.3792049 | F10: ='Sch2 Peers SEC Data'!F6/'Sch2 Peers SEC Data'!F7 -> 1.1657143 | G10: ='Sch2 Peers SEC Data'!G6/'Sch2 Peers SEC Data'!G7 -> 1.1885714 | H10: ='Sch2 Peers SEC Data'!H6/'Sch2 Peers SEC Data'!H7 -> 1.1764706 | I10: ='Sch2 Peers SEC Data'!I6/'Sch2 Peers SEC Data'!I7 -> 1.1692112 | ... N10: ='Sch2 Peers SEC Data'!N6/'Sch2 Peers SEC Data'!N7 -> 1.21
A11: DAL: Issuance-to-Revenue Ratio | B11: ='Sch2 Peers SEC Data'!B10/'Sch2 Peers SEC Data'!B11 -> 1.429878 | C11: ='Sch2 Peers SEC Data'!C10/'Sch2 Peers SEC Data'!C11 -> 1.2819444 | D11: ='Sch2 Peers SEC Data'!D10/'Sch2 Peers SEC Data'!D11 -> 1.3760331 | E11: ='Sch2 Peers SEC Data'!E10/'Sch2 Peers SEC Data'!E11 -> 1.4354005 | F11: ='Sch2 Peers SEC Data'!F10/'Sch2 Peers SEC Data'!F11 -> 1.3324905 | G11: ='Sch2 Peers SEC Data'!G10/'Sch2 Peers SEC Data'!G11 -> 1.2581047 | H11: ='Sch2 Peers SEC Data'!H10/'Sch2 Peers SEC Data'!H11 -> 1.2842767 | I11: ='Sch2 Peers SEC Data'!I10/'Sch2 Peers SEC Data'!I11 -> 1.3480861 | ... N11: ='Sch2 Peers SEC Data'!N10/'Sch2 Peers SEC Data'!N11 -> 1.4380165
A12: AAL: Issuance-to-Revenue Ratio | B12: ='Sch2 Peers SEC Data'!B14/'Sch2 Peers SEC Data'!B15 -> 1.2577488 | C12: ='Sch2 Peers SEC Data'!C14/'Sch2 Peers SEC Data'!C15 -> 0.9573991 | D12: ='Sch2 Peers SEC Data'!D14/'Sch2 Peers SEC Data'!D15 -> 1.2854812 | E12: ='Sch2 Peers SEC Data'!E14/'Sch2 Peers SEC Data'!E15 -> 2.2523191 | F12: ='Sch2 Peers SEC Data'!F14/'Sch2 Peers SEC Data'!F15 -> 1.4649266 | G12: ='Sch2 Peers SEC Data'!G14/'Sch2 Peers SEC Data'!G15 -> 0.78178694 | H12: ='Sch2 Peers SEC Data'!H14/'Sch2 Peers SEC Data'!H15 -> 1.4745547 | I12: ='Sch2 Peers SEC Data'!I14/'Sch2 Peers SEC Data'!I15 -> 1.264411 | ... N12: ='Sch2 Peers SEC Data'!N14/'Sch2 Peers SEC Data'!N15 -> 1.3044525
A14: B. STATISTICAL ANALYSIS
A15: Baseline Period | B15: Q3 2022 - Q1 2025 (11 quarters)
A16: Baseline Mean (μ) | B16: =AVERAGE(B8:L8) -> 1.8834643
A17: Baseline Std Dev (σ) | B17: =STDEV(B8:L8) -> 0.082602459
A18: Q2 2025 Observed Ratio | B18: =M8 -> 2.7428571
A19: Q2 2025 Z-Score | B19: =(B18-B16)/B17 -> 10.403962
A20: Q3 2025 Observed Ratio | B20: =N8 -> 1.87
A21: Q3 2025 Z-Score (Reversion) | B21: =(N8-B16)/B17 -> -0.16300137
A23: C. PEER COMPARISON - Q2 2025
A24: Airline | B24: Q2 2025 Ratio | C24: Baseline Mean | D24: Baseline σ | E24: Z-Score
A25: Alaska Air Group | B25: =M8 -> 2.7428571 | C25: =AVERAGE(B8:L8) -> 1.8834643 | D25: =STDEV(B8:L8) -> 0.082602459 | E25: =(B25-C25)/D25 -> 10.403962
A26: United Airlines | B26: =M10 -> 1.1997579 | C26: =AVERAGE(B10:L10) -> 1.199026 | D26: =STDEV(B10:L10) -> 0.094395246 | E26: =(B26-C26)/D26 -> 0.0077530372
A27: Delta Air Lines | B27: =M11 -> 1.4444444 | C27: =AVERAGE(B11:L11) -> 1.3594017 | D27: =STDEV(B11:L11) -> 0.06400559 | E27: =(B27-C27)/D27 -> 1.3286772
A28: American Airlines | B28: =M12 -> 1.1776316 | C28: =AVERAGE(B12:L12) -> 1.3586055 | D28: =STDEV(B12:L12) -> 0.37546045 | E28: =(B28-C28)/D28 -> -0.48200529
A30: D. EXCESS ISSUANCE CALCULATION
A31: Q2 2025 Loyalty Other Revenue ($M) | B31: =M7 -> 210
A32: Actual Q2 2025 Issuance ($M) | B32: =M6 -> 576
A33: Expected Issuance at Baseline Ratio ($M) | B33: =B31*B16 -> 395.52751
A34: Excess Issuance ($M) | B34: =B32-B33 -> 180.47249

Sheet Sch4 Partner Redemptions
A1: SCHEDULE 4: PARTNER REDEMPTION RATIO ANALYSIS
A2: The $45M Excess - Convergence with Fraud Estimate
A4: A. QUARTERLY DATA (Q1 2024 - Q3 2025)
A5: Period | B5: Q1 2024 | C5: Q2 2024 | D5: Q3 2024 | E5: Q4 2024 | F5: Q1 2025 | G5: Q2 2025 | H5: Q3 2025
A6: Partner Redemptions ($M) | B6: ='Sch1 ALK SEC Data'!H12 -> 28 | C6: ='Sch1 ALK SEC Data'!I12 -> 39 | D6: ='Sch1 ALK SEC Data'!J12 -> 46 | E6: ='Sch1 ALK SEC Data'!K12 -> 47 | F6: ='Sch1 ALK SEC Data'!L12 -> 49 | G6: ='Sch1 ALK SEC Data'!M12 -> 70 | H6: ='Sch1 ALK SEC Data'!N12 -> 75
A7: Passenger Redemptions ($M) | B7: ='Sch1 ALK SEC Data'!H11 -> 234 | C7: ='Sch1 ALK SEC Data'!I11 -> 274 | D7: ='Sch1 ALK SEC Data'!J11 -> 274 | E7: ='Sch1 ALK SEC Data'!K11 -> 342 | F7: ='Sch1 ALK SEC Data'!L11 -> 307 | G7: ='Sch1 ALK SEC Data'!M11 -> 348 | H7: ='Sch1 ALK SEC Data'!N11 -> 338
A8: Partner / Passenger Ratio | B8: =B6/B7 -> 0.11965812 | C8: =C6/C7 -> 0.14233577 | D8: =D6/D7 -> 0.16788321 | E8: =E6/E7 -> 0.1374269 | F8: =F6/F7 -> 0.15960912 | G8: =G6/G7 -> 0.20114943 | H8: =H6/H7 -> 0.22189349
A10: B. STATISTICAL ANALYSIS
A11: Baseline Period | B11: Q1 2024 - Q1 2025 (5 quarters)
A12: Baseline Mean (μ) | B12: =AVERAGE(B8:F8) -> 0.14538262
A13: Baseline Std Dev (σ) | B13: =STDEV(B8:F8) -> 0.018993398
A14: Q2 2025 Ratio | B14: =G8 -> 0.20114943
A15: Q2 2025 Z-Score | B15: =(G8-B12)/B13 -> 2.9361151
A16: Q3 2025 Ratio | B16: =H8 -> 0.22189349
A17: Q3 2025 Z-Score | B17: =(H8-B12)/B13 -> 4.0282875
A19: C. EXPECTED VS ACTUAL PARTNER REDEMPTIONS
B20: Q2 2025 | C20: Q3 2025 | D20: Total
A21: Passenger Redemptions ($M) | B21: =G7 -> 348 | C21: =H7 -> 338 | D21: =B21+C21 -> 686
A22: Expected Partner at Baseline Ratio ($M) | B22: =B21*B12 -> 50.593153 | C22: =C21*B12 -> 49.139327 | D22: =B22+C22 -> 99.73248
A23: Actual Partner Redemptions ($M) | B23: =G6 -> 70 | C23: =H6 -> 75 | D23: =B23+C23 -> 145
A24: Excess Partner Redemptions ($M) | B24: =B23-B22 -> 19.406847 | C24: =C23-C22 -> 25.860673 | D24: =B24+C24 -> 45.26752
A26: D. CONVERGENCE WITH FRAUD ESTIMATE
A27: Bottom-Up Fraud Estimate | B27: 43 | C27: 26,500 victims × 218k miles × $0.0075/mile
A28: Top-Down Excess Partner Redemptions | B28: =D24 -> 45.26752
A29: Convergence | B29: =1-ABS(B28-B27)/((ABS(B28)+ABS(B27))/2) -> 0.94862164

Sheet Sch5 Balance Sheet Trail
A1: SCHEDULE 5: BALANCE SHEET TRAIL
A2: Receivable Spike, Non-Collection, and Reclassification Analysis
A4: A. AFFINITY CARD RECEIVABLES
B5: Q4 2024 | C5: Q1 2025 | D5: Q2 2025 | E5: Q3 2025
A6: Receivables from Affinity Partners ($M) | B6: ='Sch1 ALK SEC Data'!K7 -> 176 | C6: ='Sch1 ALK SEC Data'!L7 -> 111 | D6: ='Sch1 ALK SEC Data'!M7 -> 306 | E6: ='Sch1 ALK SEC Data'!N7 -> 177
A7: Quarter-on-Quarter Change ($M) | B7: - | C7: =C6-B6 -> -65 | D7: =D6-C6 -> 195 | E7: =E6-D6 -> -129
A9: B. OTHER NON-CURRENT ASSETS
B10: Q4 2024 | C10: Q1 2025 | D10: Q2 2025 | E10: Q3 2025
A11: Other Non-Current Assets ($M) | B11: ='Sch1 ALK SEC Data'!K6 -> 334 | C11: ='Sch1 ALK SEC Data'!L6 -> 334 | D11: ='Sch1 ALK SEC Data'!M6 -> 316 | E11: ='Sch1 ALK SEC Data'!N6 -> 436
A12: Quarter-on-Quarter Change ($M) | B12: - | C12: =C11-B11 -> 0 | D12: =D11-C11 -> -18 | E12: =E11-D11 -> 120
A14: C. RECLASSIFICATION ANALYSIS
A15: Q3 2025 Receivable Decrease | B15: =E6-D6 -> -129
A16: Q3 2025 NCA Increase | B16: =E12 -> 120
A17: Implied Reclassification Amount | B17: =B16 -> 120
A19: D. RETROACTIVE RESTATEMENT (Q4 2024)
A20: Originally Reported (Q1 2025 10-Q) | B20: 118 | C20: Source: ALK Q1 2025 10-Q, Note 3
A21: Restated (Q2 2025 10-Q) | B21: 176 | C21: Source: ALK Q2 2025 10-Q, Note 3
A22: Restatement Amount | B22: =B21-B20 -> 58
A23: Restatement Percentage | B23: =B22/B20 -> 0.49152542
A25: E. MATERIALITY CONTEXT
A26: 2024 Net Income | B26: 395 | C26: Source: ALK 2024 10-K
A27: Restatement as % of Net Income | B27: =B22/B26 -> 0.14683544
A28: NCA Increase as % of Net Income | B28: =B16/B26 -> 0.30379747
A29: Standard Materiality Threshold (SAB 99) | B29: 0.05
A30: Exceeds Threshold? | B30: YES

Sheet Sch6 Materiality
A1: SCHEDULE 6: SAB 99 MATERIALITY ASSESSMENT
A3: A. QUANTITATIVE THRESHOLDS
A4: Benchmark | B4: Value ($M) | C4: Threshold % | D4: Threshold ($M)
A5: 2024 Net Income | B5: 395 | C5: 0.05 | D5: =B5*C5 -> 19.75
A6: 2024 Total Revenue | B6: 10447 | C6: 0.005 | D6: =B6*C6 -> 52.235
A7: 2024 Total Assets | B7: 20890 | C7: 0.005 | D7: =B7*C7 -> 104.45
A9: B. ESTIMATED MISSTATEMENT VS THRESHOLDS
A10: Estimated Misstatement (NCA Increase) | B10: ='Sch5 Balance Sheet Trail'!B22 -> 58
A11: Multiple of Net Income Threshold | B11: =B10/D5 -> 2.9367089
A12: Multiple of Revenue Threshold | B12: =B10/D6 -> 1.1103666
A13: Multiple of Assets Threshold | B13: =B10/D7 -> 0.55528961
A15: C. SAB 99 QUALITATIVE FACTORS
A16: Masks a change in earnings or other trends? | B16: YES | C16: Q2 spike obscures loyalty programme trajectory
A17: Hides failure to meet consensus expectations? | B17: POTENTIAL | C17: Loyalty revenue growth pattern affected
A18: Changes a loss into income or vice versa? | B18: NO | C18: Company remained profitable
A19: Affects compliance with loan covenants? | B19: POTENTIAL | C19: $2B BofA facility secured by Mileage Plan
A20: Affects compliance with regulatory requirements? | B20: YES | C20: DoT merger commitments; state breach notification
A21: Increases management compensation? | B21: UNKNOWN | C21: Compensation tied to financial metrics
A22: Involves concealment of unlawful transaction? | B22: UNDER REVIEW | C22: Potential breach notification failure

Sheet Sch7 Financial Impact
A1: SCHEDULE 7: FINANCIAL EXPOSURE METHODOLOGY
A2: Alaska Air Group, Inc. (ALK) - Revised Estimates
A3: All values in $M unless otherwise noted
A5: Parameter | B5: Conservative | C5: Central | D5: Aggressive | E5: Notes / Source
A7: SECTION A: KEY REFERENCE INPUTS
A8: Net Income 2024 ($M) | B8: 395 | C8: 395 | D8: 395 | E8: ALK 2024 10-K
A9: Central Victim Estimate | B9: 26500 | C9: 26500 | D9: 26500 | E9: Appendix B
A10: Miles per Victim | B10: 217831 | C10: 217831 | D10: 217831 | E10: 80 quantified incidents
A11: SSP per Mile ($) | B11: 0.0075 | C11: 0.0075 | D11: 0.0075 | E11: Inferred from 2024 10-K
A12: NCA Increase Q2-Q3 2025 ($M) | B12: 120 | C12: 120 | D12: 120 | E12: ALK Q3 2025 10-Q
A13: Q4 2024 Restatement ($M) | B13: 58 | C13: 58 | D13: 58 | E13: ALK Q2 2025 10-Q (restated)
A15: SECTION B: DIRECT FRAUD LOSSES
A16: Victim Multiplier | B16: 0.5 | C16: 1 | D16: 2 | E16: 0.5x to 2x central estimate
A17: Estimated Victims | B17: =B9*B16 -> 13250 | C17: =C9*C16 -> 26500 | D17: =D9*D16 -> 53000 | E17: Central × Multiplier
A18: Total Miles Stolen (billions) | B18: =B17*B10/1000000000 -> 2.8862607 | C18: =C17*C10/1000000000 -> 5.7725215 | D18: =D17*D10/1000000000 -> 11.545043 | E18: Victims × Miles per victim
A19: DIRECT FRAUD LOSS ($M) | B19: =B17*B10*B11/1000000 -> 21.646956 | C19: =C17*C10*C11/1000000 -> 43.293911 | D19: =D17*D10*D11/1000000 -> 86.587823 | E19: Victims × Miles × SSP
A21: SECTION C: RESTATEMENT / IMPAIRMENT
A22: Identified Anomaly ($M) | B22: =B12 -> 120 | C22: =C12+C13 -> 178 | D22: =D12+D13 -> 178 | E22: NCA alone (cons) vs NCA+restatement
A23: Impairment Probability (%) | B23: 0.5 | C23: 0.75 | D23: 1 | E23: Likelihood of required write-down
A24: RESTATEMENT/IMPAIRMENT ($M) | B24: =B22*B23 -> 60 | C24: =C22*C23 -> 133.5 | D24: =D22*D23 -> 178 | E24: Anomaly × Probability
A26: SECTION D: REGULATORY PENALTIES (REVISED)
A27: SEC Penalty ($M) | B27: 4 | C27: 12.5 | D27: 25 | E27: Unisys $4M to Fluor $14.5M precedents
A28: DOT Penalty ($M) | B28: 5 | C28: 20 | D28: 50 | E28: Southwest $140M; merger breach
A29: WA AG Penalty ($M) | B29: 1 | C29: 3 | D29: 10 | E29: Blackbaud WA share $2.9M
A30: FTC Penalty ($M) | B30: 3 | C30: 10 | D30: 15 | E30: Avast $16.5M precedent
A31: CFPB Penalty ($M) | B31: 5 | C31: 12 | D31: 25 | E31: Circular 2024-07; loyalty focus
A32: TOTAL REGULATORY PENALTIES ($M) | B32: =SUM(B27:B31) -> 18 | C32: =SUM(C27:C31) -> 57.5 | D32: =SUM(D27:D31) -> 125 | E32: Sum of agency penalties
A34: SECTION E: LITIGATION RESERVES (REVISED)
A35: E.1 Securities Class Action
A36: SCA Filing Probability (%) | B36: 0.4 | C36: 0.6 | D36: 0.8 | E36: Boeing-calibrated probability
A37: SCA Settlement if Filed ($M) | B37: 20 | C37: 50 | D37: 150 | E37: Boeing Fair Fund $201M precedent
A38: SCA Expected Value ($M) | B38: =B36*B37 -> 8 | C38: =C36*C37 -> 30 | D38: =D36*D37 -> 120 | E38: Probability × Settlement
A39: E.2 Consumer Class Action
A40: Consumer Filing Probability (%) | B40: 0.5 | C40: 0.7 | D40: 0.85 | E40: ADA preemption uncertainty
A41: Per-Member Recovery ($) | B41: 150 | C41: 500 | D41: 1500 | E41: Data breach settlement precedents
A42: Consumer Expected Value ($M) | B42: =B40*B17*B41/1000000 -> 0.99375 | C42: =C40*C17*C41/1000000 -> 9.275 | D42: =D40*D17*D41/1000000 -> 67.575 | E42: Prob × Class × Per-member
A43: E.3 Shareholder Derivative
A44: Derivative Filing Probability (%) | B44: 0.25 | C44: 0.4 | D44: 0.6 | E44: Board oversight failure exposure
A45: Derivative Settlement ($M) | B45: 10 | C45: 25 | D45: 75 | E45: Boeing $237.5M derivative precedent
A46: Derivative Expected Value ($M) | B46: =B44*B45 -> 2.5 | C46: =C44*C45 -> 10 | D46: =D44*D45 -> 45 | E46: Probability × Settlement
...
